Workbook

Sheet Product Tier Matrix
A1: SECTION A: PRODUCT TIER CLASSIFICATION
A2: Product Category | B2: Commission Range | C2: Tier | D2: DST Credit % | E2: Non-Direct Referral Rate
A3: Life Regular 10yr+ | B3: >30% | C3: Tier 1 | D3: 100 | E3: 15
A4: Life Regular <10yr | B4: 15-30% | C4: Tier 2 | D4: 75 | E4: 10
A5: Life ULIP | B5: <15% | C5: Tier 3 | D5: 50 | E5: 5
A6: Life Single Premium | B6: <15% | C6: Tier 3 | D6: 50 | E6: 5
A7: Health Fresh (Annual) | B7: >30% | C7: Tier 1 | D7: 100 | E7: 10
A8: Health Port/Renewal | B8: 15-30% | C8: Tier 2 | D8: 75 | E8: 7.5
A9: Health Long-Term 2yr | B9: >30% | C9: Tier 1 | D9: 100 | E9: 10
A10: Health Long-Term 3yr | B10: >30% | C10: Tier 1 | D10: 100 | E10: 10
A11: Health Quarterly/HY | B11: <15% | C11: Tier 3 | D11: 50 | E11: 5
A12: MF SIP (Monthly) | B12: <15% | C12: Tier 3 | D12: 50 | E12: 5
A13: MF LS Equity | B13: <15% | C13: Tier 3 | D13: 50 | E13: 5
A14: MF LS Debt | B14: <15% | C14: Tier 3 | D14: 50 | E14: 5
... A21: FP Route (any) | B21: >30% | C21: Tier 1 | D21: 125 | E21: 15
A24: SECTION B: CHANNEL MARGIN RULES
A25: Channel Type | B25: Typical Payout to Channel | C25: Company Margin | D25: RM Credit Basis | E25: Target Multiplier Factor
A26: Direct Sales Team (DST) | B26: 0% | C26: 100% | D26: Full credit per tier | E26: 1.0x (base)
A27: POSP Normal (70/30) | B27: 70% | C27: 30% | D27: 30% of tier credit | E27: 1.0x
A28: POSP Higher Pay (80/20) | B28: 80% | C28: 20% | D28: 20% of tier credit | E28: 1.5x
A29: POSP Very High (90/10) | B29: 90% | C29: 10% | D29: 10% of tier credit | E29: 3.0x
A30: POSP Extreme (95/5) | B30: 95% | C30: 5% | D30: 5% of tier credit | E30: 6.0x
A31: Franchise Sub-broker | B31: 10% | C31: 90% | D31: 90% of tier credit | E31: 0.33x
A32: Digital Platform (80%) | B32: 80% | C32: 20% | D32: 20% of tier credit | E32: 1.5x
A33: NOTE: Target Multiplier Factor = (30% / Company Margin %). Base is 70/30 ratio. If margin shrinks by 50%, target doubles.
A35: SECTION C: INCENTIVE SLABS — DST (DIRECT SALES TEAM)
A36: Achievement % | B36: Rate % | C36: Multiplier | D36: Status
A37: Below 80% | B37: 0 | C37: 0 | D37: No Incentive
A38: 80-100% | B38: 4 | C38: 1 | D38: Base
A39: 101-110% | B39: 5 | C39: 1.25 | D39: Standard
A40: 111-130% | B40: 6 | C40: 1.5 | D40: Enhanced
A41: 131-150% | B41: 7 | C41: 1.75 | D41: Super
A42: 151%+ | B42: 8 | C42: 2 | D42: Champion
A44: SECTION D: INCENTIVE SLABS — POSP/SUB-BROKER RM (70/30 base)
A45: Achievement % | B45: Rate % | C45: Multiplier | D45: Status
A46: Below 80% | B46: 0 | C46: 0 | D46: No Incentive
A47: 80-100% | B47: 1.2 | C47: 1 | D47: Base
A48: 101-110% | B48: 1.5 | C48: 1.25 | D48: Standard
A49: 111-130% | B49: 1.8 | C49: 1.5 | D49: Enhanced
A50: 131-150% | B50: 2.1 | C50: 1.75 | D50: Super
...

Sheet Trail Income Model
A1: SECTION A: TRAIL CALCULATION PARAMETERS
A2: Base Trail Rate (Self-Sourced, New PAN) | B2: 0.25
A3: Base Trail Rate (Existing Client, Incremental) | B3: 0.15
A4: Sub-broker Trail Factor | B4: 0.3
A5: Management Share (Self-Sourced) | B5: 0.1
A6: Management Share (Assigned + New Biz) | B6: 0.075
A7: Management Share (Assigned + No New Biz) | B7: 0.05
A8: Management Share (Office/Walk-in) | B8: 0.1
A14: SECTION B: INDIVIDUAL TRAIL CALCULATOR
A15: RM Name | B15: Starting AUM (₹) | C15: Current Total AUM (₹) | D15: Incremental AUM (₹) | E15: Client Type | F15: Channel Type | G15: Channel Payout % | H15: Company Margin % | I15: Eligible Trail Rate % | J15: Actual RM Trail % | K15: Annual Trail Income (₹) | L15: Monthly Trail Income (₹) | M15: Mgmt Share % | N15: Mgmt Trail Income (₹)
B16: 0 | C16: 0 | D16: =MAX(C16-B16,0) -> 0 | G16: 0 | H16: =1-G16 -> 1 | I16: =IF(E16="New PAN",$B$2,IF(E16="Existing Client",$B$3,0)) -> 0 | J16: =IF(F16="Direct",I16,IF(F16="Franchise",I16*0.1,I16*H16)) -> 0 | K16: =D16*J16 -> 0 | L16: =K16/12 -> 0 | M16: 0 | N16: =D16*J16*M16 -> 0
B17: 0 | C17: 0 | D17: =MAX(C17-B17,0) -> 0 | G17: 0 | H17: =1-G17 -> 1 | I17: =IF(E17="New PAN",$B$2,IF(E17="Existing Client",$B$3,0)) -> 0 | J17: =IF(F17="Direct",I17,IF(F17="Franchise",I17*0.1,I17*H17)) -> 0 | K17: =D17*J17 -> 0 | L17: =K17/12 -> 0 | M17: 0 | N17: =D17*J17*M17 -> 0
B18: 0 | C18: 0 | D18: =MAX(C18-B18,0) -> 0 | G18: 0 | H18: =1-G18 -> 1 | I18: =IF(E18="New PAN",$B$2,IF(E18="Existing Client",$B$3,0)) -> 0 | J18: =IF(F18="Direct",I18,IF(F18="Franchise",I18*0.1,I18*H18)) -> 0 | K18: =D18*J18 -> 0 | L18: =K18/12 -> 0 | M18: 0 | N18: =D18*J18*M18 -> 0
B19: 0 | C19: 0 | D19: =MAX(C19-B19,0) -> 0 | G19: 0 | H19: =1-G19 -> 1 | I19: =IF(E19="New PAN",$B$2,IF(E19="Existing Client",$B$3,0)) -> 0 | J19: =IF(F19="Direct",I19,IF(F19="Franchise",I19*0.1,I19*H19)) -> 0 | K19: =D19*J19 -> 0 | L19: =K19/12 -> 0 | M19: 0 | N19: =D19*J19*M19 -> 0
B20: 0 | C20: 0 | D20: =MAX(C20-B20,0) -> 0 | G20: 0 | H20: =1-G20 -> 1 | I20: =IF(E20="New PAN",$B$2,IF(E20="Existing Client",$B$3,0)) -> 0 | J20: =IF(F20="Direct",I20,IF(F20="Franchise",I20*0.1,I20*H20)) -> 0 | K20: =D20*J20 -> 0 | L20: =K20/12 -> 0 | M20: 0 | N20: =D20*J20*M20 -> 0
B21: 0 | C21: 0 | D21: =MAX(C21-B21,0) -> 0 | G21: 0 | H21: =1-G21 -> 1 | I21: =IF(E21="New PAN",$B$2,IF(E21="Existing Client",$B$3,0)) -> 0 | J21: =IF(F21="Direct",I21,IF(F21="Franchise",I21*0.1,I21*H21)) -> 0 | K21: =D21*J21 -> 0 | L21: =K21/12 -> 0 | M21: 0 | N21: =D21*J21*M21 -> 0
B22: 0 | C22: 0 | D22: =MAX(C22-B22,0) -> 0 | G22: 0 | H22: =1-G22 -> 1 | I22: =IF(E22="New PAN",$B$2,IF(E22="Existing Client",$B$3,0)) -> 0 | J22: =IF(F22="Direct",I22,IF(F22="Franchise",I22*0.1,I22*H22)) -> 0 | K22: =D22*J22 -> 0 | L22: =K22/12 -> 0 | M22: 0 | N22: =D22*J22*M22 -> 0
B23: 0 | C23: 0 | D23: =MAX(C23-B23,0) -> 0 | G23: 0 | H23: =1-G23 -> 1 | I23: =IF(E23="New PAN",$B$2,IF(E23="Existing Client",$B$3,0)) -> 0 | J23: =IF(F23="Direct",I23,IF(F23="Franchise",I23*0.1,I23*H23)) -> 0 | K23: =D23*J23 -> 0 | L23: =K23/12 -> 0 | M23: 0 | N23: =D23*J23*M23 -> 0
B24: 0 | C24: 0 | D24: =MAX(C24-B24,0) -> 0 | G24: 0 | H24: =1-G24 -> 1 | I24: =IF(E24="New PAN",$B$2,IF(E24="Existing Client",$B$3,0)) -> 0 | J24: =IF(F24="Direct",I24,IF(F24="Franchise",I24*0.1,I24*H24)) -> 0 | K24: =D24*J24 -> 0 | L24: =K24/12 -> 0 | M24: 0 | N24: =D24*J24*M24 -> 0
B25: 0 | C25: 0 | D25: =MAX(C25-B25,0) -> 0 | G25: 0 | H25: =1-G25 -> 1 | I25: =IF(E25="New PAN",$B$2,IF(E25="Existing Client",$B$3,0)) -> 0 | J25: =IF(F25="Direct",I25,IF(F25="Franchise",I25*0.1,I25*H25)) -> 0 | K25: =D25*J25 -> 0 | L25: =K25/12 -> 0 | M25: 0 | N25: =D25*J25*M25 -> 0
B26: 0 | C26: 0 | D26: =MAX(C26-B26,0) -> 0 | G26: 0 | H26: =1-G26 -> 1 | I26: =IF(E26="New PAN",$B$2,IF(E26="Existing Client",$B$3,0)) -> 0 | J26: =IF(F26="Direct",I26,IF(F26="Franchise",I26*0.1,I26*H26)) -> 0 | K26: =D26*J26 -> 0 | L26: =K26/12 -> 0 | M26: 0 | N26: =D26*J26*M26 -> 0
B27: 0 | C27: 0 | D27: =MAX(C27-B27,0) -> 0 | G27: 0 | H27: =1-G27 -> 1 | I27: =IF(E27="New PAN",$B$2,IF(E27="Existing Client",$B$3,0)) -> 0 | J27: =IF(F27="Direct",I27,IF(F27="Franchise",I27*0.1,I27*H27)) -> 0 | K27: =D27*J27 -> 0 | L27: =K27/12 -> 0 | M27: 0 | N27: =D27*J27*M27 -> 0
... B35: 0 | C35: 0 | D35: =MAX(C35-B35,0) -> 0 | G35: 0 | H35: =1-G35 -> 1 | I35: =IF(E35="New PAN",$B$2,IF(E35="Existing Client",$B$3,0)) -> 0 | J35: =IF(F35="Direct",I35,IF(F35="Franchise",I35*0.1,I35*H35)) -> 0 | K35: =D35*J35 -> 0 | L35: =K35/12 -> 0 | M35: 0 | N35: =D35*J35*M35 -> 0

Sheet Channel Margin Calc
A1: CHANNEL MARGIN CALCULATION & TARGET ADJUSTMENT
A2: RM Name | B2: Segment | C2: Base Salary | D2: Channel Type | E2: Avg Channel Payout % | F2: Company Margin % | G2: Base Target (DST=6×, POSP=20×) | H2: Target Multiplier Factor | I2: Adjusted Monthly Target | J2: Applicable Slab Table | K2: Notes
A3: Balbinder Kaur | C3: 0 | D3: Direct | E3: 0 | F3: =1-E3 -> 1 | G3: 0 | H3: =IF(F3=0,1,0.3/F3) -> 0.3 | I3: =G3*H3/12 -> 0 | J3: =IF(D3="Direct","DST Slabs","POSP RM Slabs") -> DST Slabs
A4: Pranab Kumar Barman | C4: 0 | D4: Direct | E4: 0 | F4: =1-E4 -> 1 | G4: 0 | H4: =IF(F4=0,1,0.3/F4) -> 0.3 | I4: =G4*H4/12 -> 0 | J4: =IF(D4="Direct","DST Slabs","POSP RM Slabs") -> DST Slabs
A5: Ajanta Saikia | C5: 0 | D5: Direct | E5: 0 | F5: =1-E5 -> 1 | G5: 0 | H5: =IF(F5=0,1,0.3/F5) -> 0.3 | I5: =G5*H5/12 -> 0 | J5: =IF(D5="Direct","DST Slabs","POSP RM Slabs") -> DST Slabs
A6: Akash Kumar | C6: 0 | D6: Direct | E6: 0 | F6: =1-E6 -> 1 | G6: 0 | H6: =IF(F6=0,1,0.3/F6) -> 0.3 | I6: =G6*H6/12 -> 0 | J6: =IF(D6="Direct","DST Slabs","POSP RM Slabs") -> DST Slabs
A7: Nipa Das | C7: 0 | D7: Direct | E7: 0 | F7: =1-E7 -> 1 | G7: 0 | H7: =IF(F7=0,1,0.3/F7) -> 0.3 | I7: =G7*H7/12 -> 0 | J7: =IF(D7="Direct","DST Slabs","POSP RM Slabs") -> DST Slabs
A8: Jitender Roy | C8: 0 | D8: Direct | E8: 0 | F8: =1-E8 -> 1 | G8: 0 | H8: =IF(F8=0,1,0.3/F8) -> 0.3 | I8: =G8*H8/12 -> 0 | J8: =IF(D8="Direct","DST Slabs","POSP RM Slabs") -> DST Slabs
A9: Rafiqueddin Ahmed | C9: 0 | D9: Direct | E9: 0 | F9: =1-E9 -> 1 | G9: 0 | H9: =IF(F9=0,1,0.3/F9) -> 0.3 | I9: =G9*H9/12 -> 0 | J9: =IF(D9="Direct","DST Slabs","POSP RM Slabs") -> DST Slabs
A10: Pranita Saikia | C10: 0 | D10: Direct | E10: 0 | F10: =1-E10 -> 1 | G10: 0 | H10: =IF(F10=0,1,0.3/F10) -> 0.3 | I10: =G10*H10/12 -> 0 | J10: =IF(D10="Direct","DST Slabs","POSP RM Slabs") -> DST Slabs
A11: Tamanna Kejriwal | C11: 0 | D11: Direct | E11: 0 | F11: =1-E11 -> 1 | G11: 0 | H11: =IF(F11=0,1,0.3/F11) -> 0.3 | I11: =G11*H11/12 -> 0 | J11: =IF(D11="Direct","DST Slabs","POSP RM Slabs") -> DST Slabs
A12: Shivani Kumari | C12: 0 | D12: Direct | E12: 0 | F12: =1-E12 -> 1 | G12: 0 | H12: =IF(F12=0,1,0.3/F12) -> 0.3 | I12: =G12*H12/12 -> 0 | J12: =IF(D12="Direct","DST Slabs","POSP RM Slabs") -> DST Slabs
A13: Rinjima Pathak Das | C13: 0 | D13: Direct | E13: 0 | F13: =1-E13 -> 1 | G13: 0 | H13: =IF(F13=0,1,0.3/F13) -> 0.3 | I13: =G13*H13/12 -> 0 | J13: =IF(D13="Direct","DST Slabs","POSP RM Slabs") -> DST Slabs
A14: Nayanjyoti Handique | C14: 0 | D14: Direct | E14: 0 | F14: =1-E14 -> 1 | G14: 0 | H14: =IF(F14=0,1,0.3/F14) -> 0.3 | I14: =G14*H14/12 -> 0 | J14: =IF(D14="Direct","DST Slabs","POSP RM Slabs") -> DST Slabs
... A22: Raj Das | C22: 0 | D22: Direct | E22: 0 | F22: =1-E22 -> 1 | G22: 0 | H22: =IF(F22=0,1,0.3/F22) -> 0.3 | I22: =G22*H22/12 -> 0 | J22: =IF(D22="Direct","DST Slabs","POSP RM Slabs") -> DST Slabs

Sheet Employee Master
A1: Sl No | B1: Name | C1: Code | D1: DOJ | E1: Designation | F1: Department | G1: Job Responsibility | H1: Gross Salary | I1: Entity | J1: Annual CTC | K1: Tenure Years | L1: Level Code | M1: Target Multiplier | N1: Monthly Target | O1: Annual Target | P1: Cost Recovery Min | Q1: Segment | R1: Target Notes
A2: 1 | B2: Balbinder Kaur | C2: TAS001 | D2: 41334 | E2: Inhouse Sales Manager | F2: OPERATION | G2: SALES | H2: 36017 | I2: TAS | J2: =H2*12 -> 432204 | K2: =YEARFRAC(D2,TODAY(),1) -> 13.077254 | M2: 6 | N2: =H2*M2 -> 216102 | O2: =N2*12 -> 2593224 | P2: =H2*1.6 -> 57627.2 | Q2: Direct | R2: Monthly target = 6× monthly salary
A3: 2 | B3: Pranab Kumar Barman | C3: TAS002 | D3: 41897 | E3: Office Assistant | F3: OPERATION | G3: ADMIN | H3: 21429 | I3: TAS | J3: =H3*12 -> 257148 | K3: =YEARFRAC(D3,TODAY(),1) -> 11.535173 | P3: =H3*1.6 -> 34286.4 | Q3: Support | R3: No sales target
A4: 3 | B4: Ajanta Saikia | C4: TAS003 | D4: 43496 | E4: Field Force Multiplier | F4: LIFE | G4: SALES | H4: 99751 | I4: TIB | J4: =H4*12 -> 1197012 | K4: =YEARFRAC(D4,TODAY(),1) -> 7.156742 | M4: 6 | N4: =H4*M4 -> 598506 | O4: =N4*12 -> 7182072 | P4: =H4*1.6 -> 159601.6 | Q4: Direct | R4: Monthly target = 6× monthly salary
A5: 4 | B5: Akash Kumar | C5: TAS004 | D5: 44075 | E5: Executive | F5: HEALTH | G5: SALES | H5: 22449 | I5: TIB | J5: =H5*12 -> 269388 | K5: =YEARFRAC(D5,TODAY(),1) -> 5.5709816 | M5: 20 | N5: =H5*M5 -> 448980 | O5: =N5*12 -> 5387760 | P5: =H5*1.6 -> 35918.4 | Q5: POSP | R5: Monthly target = 20× monthly salary
A6: 5 | B6: Nipa Das | C6: TAS005 | D6: 44151 | E6: Back Office Executive | F6: OPERATION | G6: Back Office | H6: 22263 | I6: TAS | J6: =H6*12 -> 267156 | K6: =YEARFRAC(D6,TODAY(),1) -> 5.3629253 | P6: =H6*1.6 -> 35620.8 | Q6: Support | R6: No sales target
A7: 6 | B7: Jitender Roy | C7: TAS006 | D7: 44383 | E7: Relationship Manager | F7: HEALTH | G7: SALES | H7: 40440 | I7: TIB | J7: =H7*12 -> 485280 | K7: =YEARFRAC(D7,TODAY(),1) -> 4.7293473 | M7: 20 | N7: =H7*M7 -> 808800 | O7: =N7*12 -> 9705600 | P7: =H7*1.6 -> 64704 | Q7: POSP | R7: Monthly target = 20× monthly salary
A8: 7 | B8: Rafiqueddin Ahmed | C8: TAS051 | D8: 44386 | E8: Mentor | F8: OPERATION | G8: SALES | H8: 30000 | I8: TAS | J8: =H8*12 -> 360000 | K8: =YEARFRAC(D8,TODAY(),1) -> 4.7211319 | M8: 6 | N8: =H8*M8 -> 180000 | O8: =N8*12 -> 2160000 | P8: =H8*1.6 -> 48000 | Q8: Direct | R8: Monthly target = 6× monthly salary
A9: 8 | B9: Pranita Saikia | C9: TAS008 | D9: 44406 | E9: Back Office Executive | F9: G.I. | G9: Back Office | H9: 34500 | I9: TIB | J9: =H9*12 -> 414000 | K9: =YEARFRAC(D9,TODAY(),1) -> 4.6663624 | P9: =H9*1.6 -> 55200 | Q9: Support | R9: No sales target
A10: 9 | B10: Tamanna Kejriwal | C10: TAS009 | D10: 44734 | E10: Sales Head | F10: F.P. | G10: SALES | H10: 90000 | I10: TAS | J10: =H10*12 -> 1080000 | K10: =YEARFRAC(D10,TODAY(),1) -> 3.7677985 | M10: 6 | N10: =H10*M10 -> 540000 | O10: =N10*12 -> 6480000 | P10: =H10*1.6 -> 144000 | Q10: Direct | R10: Monthly target = 6× monthly salary
A11: 10 | B11: Shivani Kumari | C11: TAS013 | D11: 44805 | E11: Back Office Executive | F11: OPERATION | G11: Back Office | H11: 16749 | I11: TAS | J11: =H11*12 -> 200988 | K11: =YEARFRAC(D11,TODAY(),1) -> 3.5733844 | P11: =H11*1.6 -> 26798.4 | Q11: Support | R11: No sales target
A12: 11 | B12: Rinjima Pathak Das | C12: TAS014 | D12: 44929 | E12: HR Manager | F12: ADMIN | G12: HR & ADMIN | H12: 46876 | I12: TIB | J12: =H12*12 -> 562512 | K12: =YEARFRAC(D12,TODAY(),1) -> 3.2334018 | P12: =H12*1.6 -> 75001.6 | Q12: Support | R12: No sales target
A13: 12 | B13: Nayanjyoti Handique | C13: TAS016 | D13: 44977 | E13: Operation Manager | F13: HEALTH | G13: Claims | H13: 29700 | I13: TIB | J13: =H13*12 -> 356400 | K13: =YEARFRAC(D13,TODAY(),1) -> 3.1019849 | P13: =H13*1.6 -> 47520 | Q13: Support | R13: No sales target
A14: 13 | B14: Laxman Sharma | C14: TAS018 | D14: 45078 | E14: Relationship Manager | F14: LIFE | G14: SALES | H14: 43700 | I14: TIB | J14: =H14*12 -> 524400 | K14: =YEARFRAC(D14,TODAY(),1) -> 2.825462 | M14: 20 | N14: =H14*M14 -> 874000 | O14: =N14*12 -> 10488000 | P14: =H14*1.6 -> 69920 | Q14: POSP | R14: Monthly target = 20× monthly salary
A15: 14 | B15: Mayurakshi Goswami | C15: TAS021 | D15: 45202 | E15: Back Office Executive | F15: OPERATION | G15: Back Office | H15: 14858 | I15: TAS | J15: =H15*12 -> 178296 | K15: =YEARFRAC(D15,TODAY(),1) -> 2.4859685 | P15: =H15*1.6 -> 23772.8 | Q15: Support | R15: No sales target
A16: 15 | B16: Bhola Singh | C16: TAS019 | D16: 45204 | E16: Area Manager GI | F16: G.I. | G16: SALES | H16: 103500 | I16: TIB | J16: =H16*12 -> 1242000 | K16: =YEARFRAC(D16,TODAY(),1) -> 2.4804928 | M16: 23 | N16: =H16*M16 -> 2380500 | O16: =N16*12 -> 28566000 | P16: =H16*1.6 -> 165600 | Q16: Area Manager | R16: Monthly target = 20× (salary+15% variable). 15% added for rent/support staff.
A17: 16 | B17: Ranjan Jyoti DC | C17: TAS022 | D17: 45337 | E17: Account Manager | F17: ACCOUNTS | G17: ADMIN | H17: 54000 | I17: TAS | J17: =H17*12 -> 648000 | K17: =YEARFRAC(D17,TODAY(),1) -> 2.1158759 | P17: =H17*1.6 -> 86400 | Q17: Support | R17: No sales target
A18: 17 | B18: Pinki Rani Kalita | C18: TAS027 | D18: 45444 | E18: Back Office Executive | F18: G.I. | G18: Back Office | H18: 15691 | I18: TIB | J18: =H18*12 -> 188292 | K18: =YEARFRAC(D18,TODAY(),1) -> 1.8229927 | P18: =H18*1.6 -> 25105.6 | Q18: Support | R18: No sales target
A19: 18 | B19: Harshita Jalan | C19: TAS032 | D19: 45474 | E19: Back Office Executive | F19: OPERATION | G19: SALES | H19: 18011 | I19: TAS | J19: =H19*12 -> 216132 | K19: =YEARFRAC(D19,TODAY(),1) -> 1.7408759 | M19: 6 | N19: =H19*M19 -> 108066 | O19: =N19*12 -> 1296792 | P19: =H19*1.6 -> 28817.6 | Q19: Direct | R19: Monthly target = 6× monthly salary
A20: 19 | B20: Lucky Pathak | C20: TAS034 | D20: 45474 | E20: Back Office Executive | F20: OPERATION | G20: Back Office | H20: 22449 | I20: TAS | J20: =H20*12 -> 269388 | K20: =YEARFRAC(D20,TODAY(),1) -> 1.7408759 | P20: =H20*1.6 -> 35918.4 | Q20: Support | R20: No sales target
A21: 20 | B21: Raj Das | C21: TAS031 | D21: 45474 | E21: Financial Planner Officer | F21: DEMAT | G21: SALES | H21: 27008 | I21: TAS | J21: =H21*12 -> 324096 | K21: =YEARFRAC(D21,TODAY(),1) -> 1.7408759 | M21: 6 | N21: =H21*M21 -> 162048 | O21: =N21*12 -> 1944576 | P21: =H21*1.6 -> 43212.8 | Q21: Direct | R21: Monthly target = 6× monthly salary
A22: 21 | B22: Vinita Kabra | C22: TAS030 | D22: 45474 | E22: Relationship Manager | F22: F.P. | G22: SALES | H22: 43200 | I22: TIB | J22: =H22*12 -> 518400 | K22: =YEARFRAC(D22,TODAY(),1) -> 1.7408759 | M22: 6 | N22: =H22*M22 -> 259200 | O22: =N22*12 -> 3110400 | P22: =H22*1.6 -> 69120 | Q22: Direct | R22: Monthly target = 6× monthly salary
A23: 22 | B23: Sudeep Kashyap | C23: TAS037 | D23: 45523 | E23: Digital Marketing Exec | F23: DIGITAL & IT | G23: SALES | H23: 28200 | I23: TAS | J23: =H23*12 -> 338400 | K23: =YEARFRAC(D23,TODAY(),1) -> 1.6067518 | M23: 6 | N23: =H23*M23 -> 169200 | O23: =N23*12 -> 2030400 | P23: =H23*1.6 -> 45120 | Q23: Direct | R23: Monthly target = 6× monthly salary
A24: 23 | B24: Jasmine Jain | C24: TAS040 | D24: 45537 | E24: RM & Trainer | F24: F.P. | G24: SALES | H24: 28200 | I24: TAS | J24: =H24*12 -> 338400 | K24: =YEARFRAC(D24,TODAY(),1) -> 1.5684307 | M24: 6 | N24: =H24*M24 -> 169200 | O24: =N24*12 -> 2030400 | P24: =H24*1.6 -> 45120 | Q24: Direct | R24: Monthly target = 6× monthly salary
A25: 24 | B25: Hira Shrestha | C25: TAS047 | D25: 45600 | E25: Back Office Executive | F25: HEALTH | G25: Claims | H25: 23200 | I25: TIB | J25: =H25*12 -> 278400 | K25: =YEARFRAC(D25,TODAY(),1) -> 1.3959854 | P25: =H25*1.6 -> 37120 | Q25: Support | R25: No sales target
A26: 25 | B26: Nisha Koirala | C26: TAS048 | D26: 45600 | E26: Back Office Executive | F26: HEALTH | G26: Claims | H26: 23200 | I26: TIB | J26: =H26*12 -> 278400 | K26: =YEARFRAC(D26,TODAY(),1) -> 1.3959854 | P26: =H26*1.6 -> 37120 | Q26: Support | R26: No sales target
A27: 26 | B27: Preeti Nag | C27: TAS050 | D27: 45601 | E27: Designer & Video Editor | F27: DIGITAL & IT | G27: SALES | H27: 13286 | I27: TAS | J27: =H27*12 -> 159432 | K27: =YEARFRAC(D27,TODAY(),1) -> 1.3932482 | M27: 6 | N27: =H27*M27 -> 79716 | O27: =N27*12 -> 956592 | P27: =H27*1.6 -> 21257.6 | Q27: Direct | R27: Monthly target = 6× monthly salary
A28: 27 | B28: Jinu Lagachu | C28: TAS052 | D28: 45610 | E28: Relationship Manager | F28: F.P. | G28: SALES | H28: 23200 | I28: TAS | J28: =H28*12 -> 278400 | K28: =YEARFRAC(D28,TODAY(),1) -> 1.3686131 | M28: 6 | N28: =H28*M28 -> 139200 | O28: =N28*12 -> 1670400 | P28: =H28*1.6 -> 37120 | Q28: Direct | R28: Monthly target = 6× monthly salary
A29: 28 | B29: Khushbu Chhajer | C29: TAS054 | D29: 45664 | E29: Sales Manager | F29: LIFE | G29: SALES | H29: 38200 | I29: TIB | J29: =H29*12 -> 458400 | K29: =YEARFRAC(D29,TODAY(),1) -> 1.2219178 | M29: 6 | N29: =H29*M29 -> 229200 | O29: =N29*12 -> 2750400 | P29: =H29*1.6 -> 61120 | Q29: Direct | R29: Monthly target = 6× monthly salary
A30: 29 | B30: Aruna Deka | C30: TAS055 | D30: 45719 | E30: Back Office Executive | F30: OPERATION | G30: Back Office | H30: 16600 | I30: TAS | J30: =H30*12 -> 199200 | K30: =YEARFRAC(D30,TODAY(),1) -> 1.0712329 | P30: =H30*1.6 -> 26560 | Q30: Support | R30: No sales target
A31: 30 | B31: Dipankar Das | C31: TAS058 | D31: 45754 | E31: Outbound Team Leader | F31: HEALTH | G31: SALES | H31: 48200 | I31: TIB | J31: =H31*12 -> 578400 | K31: =YEARFRAC(D31,TODAY(),1) -> 0.97534247 | M31: 6 | N31: =H31*M31 -> 289200 | O31: =N31*12 -> 3470400 | P31: =H31*1.6 -> 77120 | Q31: Direct | R31: Monthly target = 6× monthly salary
A32: 31 | B32: Sweety Sarania | C32: TAS061 | D32: 45763 | E32: Back Office Executive | F32: OPERATION | G32: Back Office | H32: 9842 | I32: TIB | J32: =H32*12 -> 118104 | K32: =YEARFRAC(D32,TODAY(),1) -> 0.95068493 | P32: =H32*1.6 -> 15747.2 | Q32: Support | R32: No sales target
A33: 32 | B33: Tanima Das | C33: TAS059 | D33: 45763 | E33: Tele Calling Executive | F33: OPERATION | G33: SALES | H33: 16209 | I33: TIB | J33: =H33*12 -> 194508 | K33: =YEARFRAC(D33,TODAY(),1) -> 0.95068493 | M33: 6 | N33: =H33*M33 -> 97254 | O33: =N33*12 -> 1167048 | P33: =H33*1.6 -> 25934.4 | Q33: Direct | R33: Monthly target = 6× monthly salary
A34: 33 | B34: Mrinmoy Choudhury | C34: TAS063 | D34: 45810 | E34: Regional Team Expansion Mgr | F34: HEALTH | G34: SALES | H34: 95833 | I34: TIB | J34: =H34*12 -> 1149996 | K34: =YEARFRAC(D34,TODAY(),1) -> 0.82191781 | M34: 23 | N34: =H34*M34 -> 2204159 | O34: =N34*12 -> 26449908 | P34: =H34*1.6 -> 153332.8 | Q34: Area Manager | R34: Monthly target = 20× (salary+15% variable). 15% added for rent/support staff.
A35: 34 | B35: Jumma Ara Begum | C35: TAS064 | D35: 45839 | E35: Senior HR Executive | F35: ADMIN | G35: HR & ADMIN | H35: 32451 | I35: TAS | J35: =H35*12 -> 389412 | K35: =YEARFRAC(D35,TODAY(),1) -> 0.74246575 | P35: =H35*1.6 -> 51921.6 | Q35: Support | R35: No sales target
A36: 35 | B36: Banshika Agarwal | C36: TAS067 | D36: 45854 | E36: Relationship Manager | F36: F.P. | G36: SALES | H36: 13507 | I36: TAS | J36: =H36*12 -> 162084 | K36: =YEARFRAC(D36,TODAY(),1) -> 0.70136986 | M36: 6 | N36: =H36*M36 -> 81042 | O36: =N36*12 -> 972504 | P36: =H36*1.6 -> 21611.2 | Q36: Direct | R36: Monthly target = 6× monthly salary
A37: 36 | B37: Wasbir Ahmed | C37: TAS068 | D37: 45854 | E37: Ops & CS Manager | F37: OPERATION | G37: Back Office | H37: 37897 | I37: TAS | J37: =H37*12 -> 454764 | K37: =YEARFRAC(D37,TODAY(),1) -> 0.70136986 | P37: =H37*1.6 -> 60635.2 | Q37: Support | R37: No sales target
A38: 37 | B38: Ajay Singh | C38: TAS077 | D38: 45873 | E38: MIS & POS Handling | F38: OPERATION | G38: MIS | H38: 17600 | I38: TIB | J38: =H38*12 -> 211200 | K38: =YEARFRAC(D38,TODAY(),1) -> 0.64931507 | P38: =H38*1.6 -> 28160 | Q38: Support | R38: No sales target
A39: 38 | B39: Banajit Bezbaruah | C39: TAS074 | D39: 45873 | E39: Asst. Manager | F39: G.I. | G39: SALES | H39: 30363 | I39: TIB | J39: =H39*12 -> 364356 | K39: =YEARFRAC(D39,TODAY(),1) -> 0.64931507 | M39: 6 | N39: =H39*M39 -> 182178 | O39: =N39*12 -> 2186136 | P39: =H39*1.6 -> 48580.8 | Q39: Direct | R39: Monthly target = 6× monthly salary
A40: 39 | B40: Kshetrimayam AK Singh | C40: TAS083 | D40: 45936 | E40: Ass. Branch Manager | F40: HEALTH | G40: SALES | H40: 44035 | I40: TIB | J40: =H40*12 -> 528420 | K40: =YEARFRAC(D40,TODAY(),1) -> 0.47671233 | M40: 20 | N40: =H40*M40 -> 880700 | O40: =N40*12 -> 10568400 | P40: =H40*1.6 -> 70456 | Q40: POSP | R40: Monthly target = 20× monthly salary
...

Sheet Product Credit Rules
A1: SECTION A: MUTUAL FUND CREDITS
A2: Product | B2: Credit % | C2: Notes
A3: MF SIP (Monthly Business) | B3: 100 | C3: 100% of that month's SIP collection only. NO annualization. Clawback if SIP stopped/redeemed. | D3: RETENTION RULE
A4: MF Lumpsum - Equity | B4: 10 | C4: Low margin on lumpsum equity
A5: MF Lumpsum - Long Term Debt | B5: 7.5 | C5: Medium-term debt funds
A6: MF Lumpsum - Short Term Debt | B6: 5 | C6: Low-margin liquid/ultra-short
A7: MF Debt→Equity via STP Route | B7: 10 | C7: Same as equity LS since converting
A8: FP Route Client SIP | B8: 125 | C8: BONUS: Full FP done + investment data
A9: FP Route Client Health | B9: 125 | C9: BONUS: FP validation required
A10: FP Route Client Term Life | B10: 125 | C10: BONUS: FP validation required
A11: POSP Business (Normal Grade) | B11: 30 | C11: Standard POSP credit
A12: POSP Business (Higher Pay Grade) | B12: 0 | C12: Lower % proportionate to POSP payout
A13: Franchise Business | B13: 15 | C13: Lower margin franchise model
A14: Directors' Business Credit | B14: 30 | C14: Business from Ram/Sangita Shah
A15: NOTE: FP Route 125% requires (1) Complete FP data (2) Maker-Checker verification
A16: SIP CLAWBACK: If any SIP is stopped or redeemed, the amount gets DEBITED from that month's business credit. | C16: Anti-misselling & retention tool. Discourages start-stop behavior.
A17: SECTION B: LIFE INSURANCE CREDITS
A18: Product | B18: Credit %
A19: Life - Regular Pay 10 Years+ | B19: 125
A20: Life - Regular Pay Below 10 Years | B20: 100
A21: Life - ULIP Regular Pay | B21: 25
A22: Life - Single Premium | B22: 10
A24: SECTION C: HEALTH INSURANCE CREDITS
A25: SECTION G: INCENTIVE SLABS — DIRECT SALES TEAM (DST) | B25: Credit % | C25: Formula
A26: Achievement % | B26: Rate % | C26: Multiplier | D26: Status
A27: Below 80% | B27: 0 | C27: 0 | D27: No Incentive
A28: 80-100% | B28: 4 | C28: 1 | D28: Base
A29: 101-110% | B29: 5 | C29: 1.25 | D29: Standard
A30: 111-130% | B30: 6 | C30: 1.5 | D30: Enhanced
A31: 131-150% | B31: 7 | C31: 1.75 | D31: Super
A32: 151%+ | B32: 8 | C32: 2 | D32: Champion
A33: Category | B33: Sub-Category | C33: Credit % | D33: Notes
A34: SECTION H: INCENTIVE SLABS — POSP/SUB-BROKER RM (70/30 base) | B34: Pvt Car | C34: Grid-Based | D34: Varies by insurer grid
A35: Achievement % | B35: Rate % | C35: Multiplier | D35: Status
A36: Below 80% | B36: 0 | C36: 0 | D36: No Incentive
A37: 80-100% | B37: 1.2 | C37: 1 | D37: Base
A38: 101-110% | B38: 1.5 | C38: 1.25 | D38: Standard
A39: 111-130% | B39: 1.8 | C39: 1.5 | D39: Enhanced
A40: 131-150% | B40: 2.1 | C40: 1.75 | D40: Super
A41: 151%+ | B41: 2 | C41: 2 | D41: Champion
...

Sheet Monthly Incentive Calc
A1: Sl No | B1: Name | C1: Salary | D1: Monthly Target | E1: Month | F1: Life Ins New Biz | G1: Health Ins New Biz | H1: Health Pay Type | I1: GI Motor Pvt Car | J1: GI Motor CV | K1: GI Motor TP Only | L1: GI Non-Motor | M1: GI GMC/GPA | N1: MF SIP Monthly | O1: MF LS Equity | P1: MF LS LT Debt | Q1: MF LS ST Debt | R1: MF STP Debt→Equity | S1: POSP Channel Biz | T1: Franchise Biz | U1: FP Route? | V1: Renewal Retention % | W1: Weighted Business | X1: Achievement % | Y1: Slab | Z1: Incentive Rate | AA1: Incentive Amount | AB1: Total Earning | AC1: Cost Justified | AD1: Performance Status | AE1: SIP Clawback Debit | AF1: Motor Biz Slab Rate | AG1: Channel Payout % | AH1: Company Margin % | AI1: Margin Credit Factor | AJ1: Applicable Slab
A2: 1 | B2: Balbinder Kaur | C2: ='Employee Master'!H2 -> 36017 | D2: ='Employee Master'!N2 -> 216102 | W2: =((IF(U2="Yes",F2*1.25,F2)+IF(U2="Yes",IF(H2="Annual",G2,IF(H2="2-Year",G2/2*1.25,IF(H2="3-Year",G2/3*1.5,IF(H2="Quarterly/HY",G2*0.5,G2))))*1.25,IF(H2="Annual",G2,IF(H2="2-Year",G2/2*1.25,IF(H2="3-Year",G2/3*1.5,IF(H2="Quarterly/HY",G2*0.5,G2)))))+(I2+J2+K2)+(L2+M2*0.2)+IF(U2="Yes",(N2-AE2)*1.25,(N2-AE2))+(O2*0.1+P2*0.075+Q2*0.05+R2*0.1)+(S2*0.3+T2*0.15)))*AI2 -> 0 | X2: =IF(D2=0,0,W2/D2) -> 0 | Y2: =IF(X2<0.8,"Below 80%",IF(X2<=1,"80-100%",IF(X2<=1.1,"101-110%",IF(X2<=1.3,"111-130%",IF(X2<=1.5,"131-150%","150%+"))))) -> Below 80% | Z2: =IF(AJ2="DST",IF(X2<0.8,0,IF(X2<=1,0.04,IF(X2<=1.1,0.05,IF(X2<=1.3,0.06,IF(X2<=1.5,0.07,0.08))))),IF(X2<0.8,0,IF(X2<=1,0.012,IF(X2<=1.1,0.015,IF(X2<=1.3,0.018,IF(X2<=1.5,0.021,0.02)))))) -> 0 | AA2: =W2*Z2 -> 0 | AB2: =C2+AA2 -> 36017 | AC2: =IF(W2>='Employee Master'!P2,"YES","NO") -> NO | AD2: =IF(X2>=1.3,"Star",IF(X2>=1,"High",IF(X2>=0.8,"Meets",IF(X2>=0.6,"Below","Non-Performer")))) -> Non-Performer | AE2: 0 | AF2: =IF((I2+J2+K2)=0,0,IF((I2+J2+K2)<=300000,0.015,IF((I2+J2+K2)<=500000,0.02,0.03))) -> 0 | AG2: 0 | AH2: =1-AG2 -> 1 | AI2: =IF(AH2>=1,1,AH2) -> 1 | AJ2: =IF(AG2=0,"DST","POSP RM") -> DST
A3: 2 | B3: Ajanta Saikia | C3: ='Employee Master'!H4 -> 99751 | D3: ='Employee Master'!N4 -> 598506 | W3: =((IF(U3="Yes",F3*1.25,F3)+IF(U3="Yes",IF(H3="Annual",G3,IF(H3="2-Year",G3/2*1.25,IF(H3="3-Year",G3/3*1.5,IF(H3="Quarterly/HY",G3*0.5,G3))))*1.25,IF(H3="Annual",G3,IF(H3="2-Year",G3/2*1.25,IF(H3="3-Year",G3/3*1.5,IF(H3="Quarterly/HY",G3*0.5,G3)))))+(I3+J3+K3)+(L3+M3*0.2)+IF(U3="Yes",(N3-AE3)*1.25,(N3-AE3))+(O3*0.1+P3*0.075+Q3*0.05+R3*0.1)+(S3*0.3+T3*0.15)))*AI3 -> 0 | X3: =IF(D3=0,0,W3/D3) -> 0 | Y3: =IF(X3<0.8,"Below 80%",IF(X3<=1,"80-100%",IF(X3<=1.1,"101-110%",IF(X3<=1.3,"111-130%",IF(X3<=1.5,"131-150%","150%+"))))) -> Below 80% | Z3: =IF(AJ3="DST",IF(X3<0.8,0,IF(X3<=1,0.04,IF(X3<=1.1,0.05,IF(X3<=1.3,0.06,IF(X3<=1.5,0.07,0.08))))),IF(X3<0.8,0,IF(X3<=1,0.012,IF(X3<=1.1,0.015,IF(X3<=1.3,0.018,IF(X3<=1.5,0.021,0.02)))))) -> 0 | AA3: =W3*Z3 -> 0 | AB3: =C3+AA3 -> 99751 | AC3: =IF(W3>='Employee Master'!P4,"YES","NO") -> NO | AD3: =IF(X3>=1.3,"Star",IF(X3>=1,"High",IF(X3>=0.8,"Meets",IF(X3>=0.6,"Below","Non-Performer")))) -> Non-Performer | AE3: 0 | AF3: =IF((I3+J3+K3)=0,0,IF((I3+J3+K3)<=300000,0.015,IF((I3+J3+K3)<=500000,0.02,0.03))) -> 0 | AG3: 0 | AH3: =1-AG3 -> 1 | AI3: =IF(AH3>=1,1,AH3) -> 1 | AJ3: =IF(AG3=0,"DST","POSP RM") -> DST
A4: 3 | B4: Akash Kumar | C4: ='Employee Master'!H5 -> 22449 | D4: ='Employee Master'!N5 -> 448980 | W4: =((IF(U4="Yes",F4*1.25,F4)+IF(U4="Yes",IF(H4="Annual",G4,IF(H4="2-Year",G4/2*1.25,IF(H4="3-Year",G4/3*1.5,IF(H4="Quarterly/HY",G4*0.5,G4))))*1.25,IF(H4="Annual",G4,IF(H4="2-Year",G4/2*1.25,IF(H4="3-Year",G4/3*1.5,IF(H4="Quarterly/HY",G4*0.5,G4)))))+(I4+J4+K4)+(L4+M4*0.2)+IF(U4="Yes",(N4-AE4)*1.25,(N4-AE4))+(O4*0.1+P4*0.075+Q4*0.05+R4*0.1)+(S4*0.3+T4*0.15)))*AI4 -> 0 | X4: =IF(D4=0,0,W4/D4) -> 0 | Y4: =IF(X4<0.8,"Below 80%",IF(X4<=1,"80-100%",IF(X4<=1.1,"101-110%",IF(X4<=1.3,"111-130%",IF(X4<=1.5,"131-150%","150%+"))))) -> Below 80% | Z4: =IF(AJ4="DST",IF(X4<0.8,0,IF(X4<=1,0.04,IF(X4<=1.1,0.05,IF(X4<=1.3,0.06,IF(X4<=1.5,0.07,0.08))))),IF(X4<0.8,0,IF(X4<=1,0.012,IF(X4<=1.1,0.015,IF(X4<=1.3,0.018,IF(X4<=1.5,0.021,0.02)))))) -> 0 | AA4: =W4*Z4 -> 0 | AB4: =C4+AA4 -> 22449 | AC4: =IF(W4>='Employee Master'!P5,"YES","NO") -> NO | AD4: =IF(X4>=1.3,"Star",IF(X4>=1,"High",IF(X4>=0.8,"Meets",IF(X4>=0.6,"Below","Non-Performer")))) -> Non-Performer | AE4: 0 | AF4: =IF((I4+J4+K4)=0,0,IF((I4+J4+K4)<=300000,0.015,IF((I4+J4+K4)<=500000,0.02,0.03))) -> 0 | AG4: 0 | AH4: =1-AG4 -> 1 | AI4: =IF(AH4>=1,1,AH4) -> 1 | AJ4: =IF(AG4=0,"DST","POSP RM") -> DST
A5: 4 | B5: Jitender Roy | C5: ='Employee Master'!H7 -> 40440 | D5: ='Employee Master'!N7 -> 808800 | W5: =((IF(U5="Yes",F5*1.25,F5)+IF(U5="Yes",IF(H5="Annual",G5,IF(H5="2-Year",G5/2*1.25,IF(H5="3-Year",G5/3*1.5,IF(H5="Quarterly/HY",G5*0.5,G5))))*1.25,IF(H5="Annual",G5,IF(H5="2-Year",G5/2*1.25,IF(H5="3-Year",G5/3*1.5,IF(H5="Quarterly/HY",G5*0.5,G5)))))+(I5+J5+K5)+(L5+M5*0.2)+IF(U5="Yes",(N5-AE5)*1.25,(N5-AE5))+(O5*0.1+P5*0.075+Q5*0.05+R5*0.1)+(S5*0.3+T5*0.15)))*AI5 -> 0 | X5: =IF(D5=0,0,W5/D5) -> 0 | Y5: =IF(X5<0.8,"Below 80%",IF(X5<=1,"80-100%",IF(X5<=1.1,"101-110%",IF(X5<=1.3,"111-130%",IF(X5<=1.5,"131-150%","150%+"))))) -> Below 80% | Z5: =IF(AJ5="DST",IF(X5<0.8,0,IF(X5<=1,0.04,IF(X5<=1.1,0.05,IF(X5<=1.3,0.06,IF(X5<=1.5,0.07,0.08))))),IF(X5<0.8,0,IF(X5<=1,0.012,IF(X5<=1.1,0.015,IF(X5<=1.3,0.018,IF(X5<=1.5,0.021,0.02)))))) -> 0 | AA5: =W5*Z5 -> 0 | AB5: =C5+AA5 -> 40440 | AC5: =IF(W5>='Employee Master'!P7,"YES","NO") -> NO | AD5: =IF(X5>=1.3,"Star",IF(X5>=1,"High",IF(X5>=0.8,"Meets",IF(X5>=0.6,"Below","Non-Performer")))) -> Non-Performer | AE5: 0 | AF5: =IF((I5+J5+K5)=0,0,IF((I5+J5+K5)<=300000,0.015,IF((I5+J5+K5)<=500000,0.02,0.03))) -> 0 | AG5: 0 | AH5: =1-AG5 -> 1 | AI5: =IF(AH5>=1,1,AH5) -> 1 | AJ5: =IF(AG5=0,"DST","POSP RM") -> DST
A6: 5 | B6: Rafiqueddin Ahmed | C6: ='Employee Master'!H8 -> 30000 | D6: ='Employee Master'!N8 -> 180000 | W6: =((IF(U6="Yes",F6*1.25,F6)+IF(U6="Yes",IF(H6="Annual",G6,IF(H6="2-Year",G6/2*1.25,IF(H6="3-Year",G6/3*1.5,IF(H6="Quarterly/HY",G6*0.5,G6))))*1.25,IF(H6="Annual",G6,IF(H6="2-Year",G6/2*1.25,IF(H6="3-Year",G6/3*1.5,IF(H6="Quarterly/HY",G6*0.5,G6)))))+(I6+J6+K6)+(L6+M6*0.2)+IF(U6="Yes",(N6-AE6)*1.25,(N6-AE6))+(O6*0.1+P6*0.075+Q6*0.05+R6*0.1)+(S6*0.3+T6*0.15)))*AI6 -> 0 | X6: =IF(D6=0,0,W6/D6) -> 0 | Y6: =IF(X6<0.8,"Below 80%",IF(X6<=1,"80-100%",IF(X6<=1.1,"101-110%",IF(X6<=1.3,"111-130%",IF(X6<=1.5,"131-150%","150%+"))))) -> Below 80% | Z6: =IF(AJ6="DST",IF(X6<0.8,0,IF(X6<=1,0.04,IF(X6<=1.1,0.05,IF(X6<=1.3,0.06,IF(X6<=1.5,0.07,0.08))))),IF(X6<0.8,0,IF(X6<=1,0.012,IF(X6<=1.1,0.015,IF(X6<=1.3,0.018,IF(X6<=1.5,0.021,0.02)))))) -> 0 | AA6: =W6*Z6 -> 0 | AB6: =C6+AA6 -> 30000 | AC6: =IF(W6>='Employee Master'!P8,"YES","NO") -> NO | AD6: =IF(X6>=1.3,"Star",IF(X6>=1,"High",IF(X6>=0.8,"Meets",IF(X6>=0.6,"Below","Non-Performer")))) -> Non-Performer | AE6: 0 | AF6: =IF((I6+J6+K6)=0,0,IF((I6+J6+K6)<=300000,0.015,IF((I6+J6+K6)<=500000,0.02,0.03))) -> 0 | AG6: 0 | AH6: =1-AG6 -> 1 | AI6: =IF(AH6>=1,1,AH6) -> 1 | AJ6: =IF(AG6=0,"DST","POSP RM") -> DST
A7: 6 | B7: Tamanna Kejriwal | C7: ='Employee Master'!H10 -> 90000 | D7: ='Employee Master'!N10 -> 540000 | W7: =((IF(U7="Yes",F7*1.25,F7)+IF(U7="Yes",IF(H7="Annual",G7,IF(H7="2-Year",G7/2*1.25,IF(H7="3-Year",G7/3*1.5,IF(H7="Quarterly/HY",G7*0.5,G7))))*1.25,IF(H7="Annual",G7,IF(H7="2-Year",G7/2*1.25,IF(H7="3-Year",G7/3*1.5,IF(H7="Quarterly/HY",G7*0.5,G7)))))+(I7+J7+K7)+(L7+M7*0.2)+IF(U7="Yes",(N7-AE7)*1.25,(N7-AE7))+(O7*0.1+P7*0.075+Q7*0.05+R7*0.1)+(S7*0.3+T7*0.15)))*AI7 -> 0 | X7: =IF(D7=0,0,W7/D7) -> 0 | Y7: =IF(X7<0.8,"Below 80%",IF(X7<=1,"80-100%",IF(X7<=1.1,"101-110%",IF(X7<=1.3,"111-130%",IF(X7<=1.5,"131-150%","150%+"))))) -> Below 80% | Z7: =IF(AJ7="DST",IF(X7<0.8,0,IF(X7<=1,0.04,IF(X7<=1.1,0.05,IF(X7<=1.3,0.06,IF(X7<=1.5,0.07,0.08))))),IF(X7<0.8,0,IF(X7<=1,0.012,IF(X7<=1.1,0.015,IF(X7<=1.3,0.018,IF(X7<=1.5,0.021,0.02)))))) -> 0 | AA7: =W7*Z7 -> 0 | AB7: =C7+AA7 -> 90000 | AC7: =IF(W7>='Employee Master'!P10,"YES","NO") -> NO | AD7: =IF(X7>=1.3,"Star",IF(X7>=1,"High",IF(X7>=0.8,"Meets",IF(X7>=0.6,"Below","Non-Performer")))) -> Non-Performer | AE7: 0 | AF7: =IF((I7+J7+K7)=0,0,IF((I7+J7+K7)<=300000,0.015,IF((I7+J7+K7)<=500000,0.02,0.03))) -> 0 | AG7: 0 | AH7: =1-AG7 -> 1 | AI7: =IF(AH7>=1,1,AH7) -> 1 | AJ7: =IF(AG7=0,"DST","POSP RM") -> DST
A8: 7 | B8: Laxman Sharma | C8: ='Employee Master'!H14 -> 43700 | D8: ='Employee Master'!N14 -> 874000 | W8: =((IF(U8="Yes",F8*1.25,F8)+IF(U8="Yes",IF(H8="Annual",G8,IF(H8="2-Year",G8/2*1.25,IF(H8="3-Year",G8/3*1.5,IF(H8="Quarterly/HY",G8*0.5,G8))))*1.25,IF(H8="Annual",G8,IF(H8="2-Year",G8/2*1.25,IF(H8="3-Year",G8/3*1.5,IF(H8="Quarterly/HY",G8*0.5,G8)))))+(I8+J8+K8)+(L8+M8*0.2)+IF(U8="Yes",(N8-AE8)*1.25,(N8-AE8))+(O8*0.1+P8*0.075+Q8*0.05+R8*0.1)+(S8*0.3+T8*0.15)))*AI8 -> 0 | X8: =IF(D8=0,0,W8/D8) -> 0 | Y8: =IF(X8<0.8,"Below 80%",IF(X8<=1,"80-100%",IF(X8<=1.1,"101-110%",IF(X8<=1.3,"111-130%",IF(X8<=1.5,"131-150%","150%+"))))) -> Below 80% | Z8: =IF(AJ8="DST",IF(X8<0.8,0,IF(X8<=1,0.04,IF(X8<=1.1,0.05,IF(X8<=1.3,0.06,IF(X8<=1.5,0.07,0.08))))),IF(X8<0.8,0,IF(X8<=1,0.012,IF(X8<=1.1,0.015,IF(X8<=1.3,0.018,IF(X8<=1.5,0.021,0.02)))))) -> 0 | AA8: =W8*Z8 -> 0 | AB8: =C8+AA8 -> 43700 | AC8: =IF(W8>='Employee Master'!P14,"YES","NO") -> NO | AD8: =IF(X8>=1.3,"Star",IF(X8>=1,"High",IF(X8>=0.8,"Meets",IF(X8>=0.6,"Below","Non-Performer")))) -> Non-Performer | AE8: 0 | AF8: =IF((I8+J8+K8)=0,0,IF((I8+J8+K8)<=300000,0.015,IF((I8+J8+K8)<=500000,0.02,0.03))) -> 0 | AG8: 0 | AH8: =1-AG8 -> 1 | AI8: =IF(AH8>=1,1,AH8) -> 1 | AJ8: =IF(AG8=0,"DST","POSP RM") -> DST
A9: 8 | B9: Bhola Singh | C9: ='Employee Master'!H16 -> 103500 | D9: ='Employee Master'!N16 -> 2380500 | W9: =((IF(U9="Yes",F9*1.25,F9)+IF(U9="Yes",IF(H9="Annual",G9,IF(H9="2-Year",G9/2*1.25,IF(H9="3-Year",G9/3*1.5,IF(H9="Quarterly/HY",G9*0.5,G9))))*1.25,IF(H9="Annual",G9,IF(H9="2-Year",G9/2*1.25,IF(H9="3-Year",G9/3*1.5,IF(H9="Quarterly/HY",G9*0.5,G9)))))+(I9+J9+K9)+(L9+M9*0.2)+IF(U9="Yes",(N9-AE9)*1.25,(N9-AE9))+(O9*0.1+P9*0.075+Q9*0.05+R9*0.1)+(S9*0.3+T9*0.15)))*AI9 -> 0 | X9: =IF(D9=0,0,W9/D9) -> 0 | Y9: =IF(X9<0.8,"Below 80%",IF(X9<=1,"80-100%",IF(X9<=1.1,"101-110%",IF(X9<=1.3,"111-130%",IF(X9<=1.5,"131-150%","150%+"))))) -> Below 80% | Z9: =IF(AJ9="DST",IF(X9<0.8,0,IF(X9<=1,0.04,IF(X9<=1.1,0.05,IF(X9<=1.3,0.06,IF(X9<=1.5,0.07,0.08))))),IF(X9<0.8,0,IF(X9<=1,0.012,IF(X9<=1.1,0.015,IF(X9<=1.3,0.018,IF(X9<=1.5,0.021,0.02)))))) -> 0 | AA9: =W9*Z9 -> 0 | AB9: =C9+AA9 -> 103500 | AC9: =IF(W9>='Employee Master'!P16,"YES","NO") -> NO | AD9: =IF(X9>=1.3,"Star",IF(X9>=1,"High",IF(X9>=0.8,"Meets",IF(X9>=0.6,"Below","Non-Performer")))) -> Non-Performer | AE9: 0 | AF9: =IF((I9+J9+K9)=0,0,IF((I9+J9+K9)<=300000,0.015,IF((I9+J9+K9)<=500000,0.02,0.03))) -> 0 | AG9: 0 | AH9: =1-AG9 -> 1 | AI9: =IF(AH9>=1,1,AH9) -> 1 | AJ9: =IF(AG9=0,"DST","POSP RM") -> DST
A10: 9 | B10: Harshita Jalan | C10: ='Employee Master'!H19 -> 18011 | D10: ='Employee Master'!N19 -> 108066 | W10: =((IF(U10="Yes",F10*1.25,F10)+IF(U10="Yes",IF(H10="Annual",G10,IF(H10="2-Year",G10/2*1.25,IF(H10="3-Year",G10/3*1.5,IF(H10="Quarterly/HY",G10*0.5,G10))))*1.25,IF(H10="Annual",G10,IF(H10="2-Year",G10/2*1.25,IF(H10="3-Year",G10/3*1.5,IF(H10="Quarterly/HY",G10*0.5,G10)))))+(I10+J10+K10)+(L10+M10*0.2)+IF(U10="Yes",(N10-AE10)*1.25,(N10-AE10))+(O10*0.1+P10*0.075+Q10*0.05+R10*0.1)+(S10*0.3+T10*0.15)))*AI10 -> 0 | X10: =IF(D10=0,0,W10/D10) -> 0 | Y10: =IF(X10<0.8,"Below 80%",IF(X10<=1,"80-100%",IF(X10<=1.1,"101-110%",IF(X10<=1.3,"111-130%",IF(X10<=1.5,"131-150%","150%+"))))) -> Below 80% | Z10: =IF(AJ10="DST",IF(X10<0.8,0,IF(X10<=1,0.04,IF(X10<=1.1,0.05,IF(X10<=1.3,0.06,IF(X10<=1.5,0.07,0.08))))),IF(X10<0.8,0,IF(X10<=1,0.012,IF(X10<=1.1,0.015,IF(X10<=1.3,0.018,IF(X10<=1.5,0.021,0.02)))))) -> 0 | AA10: =W10*Z10 -> 0 | AB10: =C10+AA10 -> 18011 | AC10: =IF(W10>='Employee Master'!P19,"YES","NO") -> NO | AD10: =IF(X10>=1.3,"Star",IF(X10>=1,"High",IF(X10>=0.8,"Meets",IF(X10>=0.6,"Below","Non-Performer")))) -> Non-Performer | AE10: 0 | AF10: =IF((I10+J10+K10)=0,0,IF((I10+J10+K10)<=300000,0.015,IF((I10+J10+K10)<=500000,0.02,0.03))) -> 0 | AG10: 0 | AH10: =1-AG10 -> 1 | AI10: =IF(AH10>=1,1,AH10) -> 1 | AJ10: =IF(AG10=0,"DST","POSP RM") -> DST
A11: 10 | B11: Raj Das | C11: ='Employee Master'!H21 -> 27008 | D11: ='Employee Master'!N21 -> 162048 | W11: =((IF(U11="Yes",F11*1.25,F11)+IF(U11="Yes",IF(H11="Annual",G11,IF(H11="2-Year",G11/2*1.25,IF(H11="3-Year",G11/3*1.5,IF(H11="Quarterly/HY",G11*0.5,G11))))*1.25,IF(H11="Annual",G11,IF(H11="2-Year",G11/2*1.25,IF(H11="3-Year",G11/3*1.5,IF(H11="Quarterly/HY",G11*0.5,G11)))))+(I11+J11+K11)+(L11+M11*0.2)+IF(U11="Yes",(N11-AE11)*1.25,(N11-AE11))+(O11*0.1+P11*0.075+Q11*0.05+R11*0.1)+(S11*0.3+T11*0.15)))*AI11 -> 0 | X11: =IF(D11=0,0,W11/D11) -> 0 | Y11: =IF(X11<0.8,"Below 80%",IF(X11<=1,"80-100%",IF(X11<=1.1,"101-110%",IF(X11<=1.3,"111-130%",IF(X11<=1.5,"131-150%","150%+"))))) -> Below 80% | Z11: =IF(AJ11="DST",IF(X11<0.8,0,IF(X11<=1,0.04,IF(X11<=1.1,0.05,IF(X11<=1.3,0.06,IF(X11<=1.5,0.07,0.08))))),IF(X11<0.8,0,IF(X11<=1,0.012,IF(X11<=1.1,0.015,IF(X11<=1.3,0.018,IF(X11<=1.5,0.021,0.02)))))) -> 0 | AA11: =W11*Z11 -> 0 | AB11: =C11+AA11 -> 27008 | AC11: =IF(W11>='Employee Master'!P21,"YES","NO") -> NO | AD11: =IF(X11>=1.3,"Star",IF(X11>=1,"High",IF(X11>=0.8,"Meets",IF(X11>=0.6,"Below","Non-Performer")))) -> Non-Performer | AE11: 0 | AF11: =IF((I11+J11+K11)=0,0,IF((I11+J11+K11)<=300000,0.015,IF((I11+J11+K11)<=500000,0.02,0.03))) -> 0 | AG11: 0 | AH11: =1-AG11 -> 1 | AI11: =IF(AH11>=1,1,AH11) -> 1 | AJ11: =IF(AG11=0,"DST","POSP RM") -> DST
A12: 11 | B12: Vinita Kabra | C12: ='Employee Master'!H22 -> 43200 | D12: ='Employee Master'!N22 -> 259200 | W12: =((IF(U12="Yes",F12*1.25,F12)+IF(U12="Yes",IF(H12="Annual",G12,IF(H12="2-Year",G12/2*1.25,IF(H12="3-Year",G12/3*1.5,IF(H12="Quarterly/HY",G12*0.5,G12))))*1.25,IF(H12="Annual",G12,IF(H12="2-Year",G12/2*1.25,IF(H12="3-Year",G12/3*1.5,IF(H12="Quarterly/HY",G12*0.5,G12)))))+(I12+J12+K12)+(L12+M12*0.2)+IF(U12="Yes",(N12-AE12)*1.25,(N12-AE12))+(O12*0.1+P12*0.075+Q12*0.05+R12*0.1)+(S12*0.3+T12*0.15)))*AI12 -> 0 | X12: =IF(D12=0,0,W12/D12) -> 0 | Y12: =IF(X12<0.8,"Below 80%",IF(X12<=1,"80-100%",IF(X12<=1.1,"101-110%",IF(X12<=1.3,"111-130%",IF(X12<=1.5,"131-150%","150%+"))))) -> Below 80% | Z12: =IF(AJ12="DST",IF(X12<0.8,0,IF(X12<=1,0.04,IF(X12<=1.1,0.05,IF(X12<=1.3,0.06,IF(X12<=1.5,0.07,0.08))))),IF(X12<0.8,0,IF(X12<=1,0.012,IF(X12<=1.1,0.015,IF(X12<=1.3,0.018,IF(X12<=1.5,0.021,0.02)))))) -> 0 | AA12: =W12*Z12 -> 0 | AB12: =C12+AA12 -> 43200 | AC12: =IF(W12>='Employee Master'!P22,"YES","NO") -> NO | AD12: =IF(X12>=1.3,"Star",IF(X12>=1,"High",IF(X12>=0.8,"Meets",IF(X12>=0.6,"Below","Non-Performer")))) -> Non-Performer | AE12: 0 | AF12: =IF((I12+J12+K12)=0,0,IF((I12+J12+K12)<=300000,0.015,IF((I12+J12+K12)<=500000,0.02,0.03))) -> 0 | AG12: 0 | AH12: =1-AG12 -> 1 | AI12: =IF(AH12>=1,1,AH12) -> 1 | AJ12: =IF(AG12=0,"DST","POSP RM") -> DST
A13: 12 | B13: Sudeep Kashyap | C13: ='Employee Master'!H23 -> 28200 | D13: ='Employee Master'!N23 -> 169200 | W13: =((IF(U13="Yes",F13*1.25,F13)+IF(U13="Yes",IF(H13="Annual",G13,IF(H13="2-Year",G13/2*1.25,IF(H13="3-Year",G13/3*1.5,IF(H13="Quarterly/HY",G13*0.5,G13))))*1.25,IF(H13="Annual",G13,IF(H13="2-Year",G13/2*1.25,IF(H13="3-Year",G13/3*1.5,IF(H13="Quarterly/HY",G13*0.5,G13)))))+(I13+J13+K13)+(L13+M13*0.2)+IF(U13="Yes",(N13-AE13)*1.25,(N13-AE13))+(O13*0.1+P13*0.075+Q13*0.05+R13*0.1)+(S13*0.3+T13*0.15)))*AI13 -> 0 | X13: =IF(D13=0,0,W13/D13) -> 0 | Y13: =IF(X13<0.8,"Below 80%",IF(X13<=1,"80-100%",IF(X13<=1.1,"101-110%",IF(X13<=1.3,"111-130%",IF(X13<=1.5,"131-150%","150%+"))))) -> Below 80% | Z13: =IF(AJ13="DST",IF(X13<0.8,0,IF(X13<=1,0.04,IF(X13<=1.1,0.05,IF(X13<=1.3,0.06,IF(X13<=1.5,0.07,0.08))))),IF(X13<0.8,0,IF(X13<=1,0.012,IF(X13<=1.1,0.015,IF(X13<=1.3,0.018,IF(X13<=1.5,0.021,0.02)))))) -> 0 | AA13: =W13*Z13 -> 0 | AB13: =C13+AA13 -> 28200 | AC13: =IF(W13>='Employee Master'!P23,"YES","NO") -> NO | AD13: =IF(X13>=1.3,"Star",IF(X13>=1,"High",IF(X13>=0.8,"Meets",IF(X13>=0.6,"Below","Non-Performer")))) -> Non-Performer | AE13: 0 | AF13: =IF((I13+J13+K13)=0,0,IF((I13+J13+K13)<=300000,0.015,IF((I13+J13+K13)<=500000,0.02,0.03))) -> 0 | AG13: 0 | AH13: =1-AG13 -> 1 | AI13: =IF(AH13>=1,1,AH13) -> 1 | AJ13: =IF(AG13=0,"DST","POSP RM") -> DST
A14: 13 | B14: Jasmine Jain | C14: ='Employee Master'!H24 -> 28200 | D14: ='Employee Master'!N24 -> 169200 | W14: =((IF(U14="Yes",F14*1.25,F14)+IF(U14="Yes",IF(H14="Annual",G14,IF(H14="2-Year",G14/2*1.25,IF(H14="3-Year",G14/3*1.5,IF(H14="Quarterly/HY",G14*0.5,G14))))*1.25,IF(H14="Annual",G14,IF(H14="2-Year",G14/2*1.25,IF(H14="3-Year",G14/3*1.5,IF(H14="Quarterly/HY",G14*0.5,G14)))))+(I14+J14+K14)+(L14+M14*0.2)+IF(U14="Yes",(N14-AE14)*1.25,(N14-AE14))+(O14*0.1+P14*0.075+Q14*0.05+R14*0.1)+(S14*0.3+T14*0.15)))*AI14 -> 0 | X14: =IF(D14=0,0,W14/D14) -> 0 | Y14: =IF(X14<0.8,"Below 80%",IF(X14<=1,"80-100%",IF(X14<=1.1,"101-110%",IF(X14<=1.3,"111-130%",IF(X14<=1.5,"131-150%","150%+"))))) -> Below 80% | Z14: =IF(AJ14="DST",IF(X14<0.8,0,IF(X14<=1,0.04,IF(X14<=1.1,0.05,IF(X14<=1.3,0.06,IF(X14<=1.5,0.07,0.08))))),IF(X14<0.8,0,IF(X14<=1,0.012,IF(X14<=1.1,0.015,IF(X14<=1.3,0.018,IF(X14<=1.5,0.021,0.02)))))) -> 0 | AA14: =W14*Z14 -> 0 | AB14: =C14+AA14 -> 28200 | AC14: =IF(W14>='Employee Master'!P24,"YES","NO") -> NO | AD14: =IF(X14>=1.3,"Star",IF(X14>=1,"High",IF(X14>=0.8,"Meets",IF(X14>=0.6,"Below","Non-Performer")))) -> Non-Performer | AE14: 0 | AF14: =IF((I14+J14+K14)=0,0,IF((I14+J14+K14)<=300000,0.015,IF((I14+J14+K14)<=500000,0.02,0.03))) -> 0 | AG14: 0 | AH14: =1-AG14 -> 1 | AI14: =IF(AH14>=1,1,AH14) -> 1 | AJ14: =IF(AG14=0,"DST","POSP RM") -> DST
A15: 14 | B15: Preeti Nag | C15: ='Employee Master'!H27 -> 13286 | D15: ='Employee Master'!N27 -> 79716 | W15: =((IF(U15="Yes",F15*1.25,F15)+IF(U15="Yes",IF(H15="Annual",G15,IF(H15="2-Year",G15/2*1.25,IF(H15="3-Year",G15/3*1.5,IF(H15="Quarterly/HY",G15*0.5,G15))))*1.25,IF(H15="Annual",G15,IF(H15="2-Year",G15/2*1.25,IF(H15="3-Year",G15/3*1.5,IF(H15="Quarterly/HY",G15*0.5,G15)))))+(I15+J15+K15)+(L15+M15*0.2)+IF(U15="Yes",(N15-AE15)*1.25,(N15-AE15))+(O15*0.1+P15*0.075+Q15*0.05+R15*0.1)+(S15*0.3+T15*0.15)))*AI15 -> 0 | X15: =IF(D15=0,0,W15/D15) -> 0 | Y15: =IF(X15<0.8,"Below 80%",IF(X15<=1,"80-100%",IF(X15<=1.1,"101-110%",IF(X15<=1.3,"111-130%",IF(X15<=1.5,"131-150%","150%+"))))) -> Below 80% | Z15: =IF(AJ15="DST",IF(X15<0.8,0,IF(X15<=1,0.04,IF(X15<=1.1,0.05,IF(X15<=1.3,0.06,IF(X15<=1.5,0.07,0.08))))),IF(X15<0.8,0,IF(X15<=1,0.012,IF(X15<=1.1,0.015,IF(X15<=1.3,0.018,IF(X15<=1.5,0.021,0.02)))))) -> 0 | AA15: =W15*Z15 -> 0 | AB15: =C15+AA15 -> 13286 | AC15: =IF(W15>='Employee Master'!P27,"YES","NO") -> NO | AD15: =IF(X15>=1.3,"Star",IF(X15>=1,"High",IF(X15>=0.8,"Meets",IF(X15>=0.6,"Below","Non-Performer")))) -> Non-Performer | AE15: 0 | AF15: =IF((I15+J15+K15)=0,0,IF((I15+J15+K15)<=300000,0.015,IF((I15+J15+K15)<=500000,0.02,0.03))) -> 0 | AG15: 0 | AH15: =1-AG15 -> 1 | AI15: =IF(AH15>=1,1,AH15) -> 1 | AJ15: =IF(AG15=0,"DST","POSP RM") -> DST
A16: 15 | B16: Jinu Lagachu | C16: ='Employee Master'!H28 -> 23200 | D16: ='Employee Master'!N28 -> 139200 | W16: =((IF(U16="Yes",F16*1.25,F16)+IF(U16="Yes",IF(H16="Annual",G16,IF(H16="2-Year",G16/2*1.25,IF(H16="3-Year",G16/3*1.5,IF(H16="Quarterly/HY",G16*0.5,G16))))*1.25,IF(H16="Annual",G16,IF(H16="2-Year",G16/2*1.25,IF(H16="3-Year",G16/3*1.5,IF(H16="Quarterly/HY",G16*0.5,G16)))))+(I16+J16+K16)+(L16+M16*0.2)+IF(U16="Yes",(N16-AE16)*1.25,(N16-AE16))+(O16*0.1+P16*0.075+Q16*0.05+R16*0.1)+(S16*0.3+T16*0.15)))*AI16 -> 0 | X16: =IF(D16=0,0,W16/D16) -> 0 | Y16: =IF(X16<0.8,"Below 80%",IF(X16<=1,"80-100%",IF(X16<=1.1,"101-110%",IF(X16<=1.3,"111-130%",IF(X16<=1.5,"131-150%","150%+"))))) -> Below 80% | Z16: =IF(AJ16="DST",IF(X16<0.8,0,IF(X16<=1,0.04,IF(X16<=1.1,0.05,IF(X16<=1.3,0.06,IF(X16<=1.5,0.07,0.08))))),IF(X16<0.8,0,IF(X16<=1,0.012,IF(X16<=1.1,0.015,IF(X16<=1.3,0.018,IF(X16<=1.5,0.021,0.02)))))) -> 0 | AA16: =W16*Z16 -> 0 | AB16: =C16+AA16 -> 23200 | AC16: =IF(W16>='Employee Master'!P28,"YES","NO") -> NO | AD16: =IF(X16>=1.3,"Star",IF(X16>=1,"High",IF(X16>=0.8,"Meets",IF(X16>=0.6,"Below","Non-Performer")))) -> Non-Performer | AE16: 0 | AF16: =IF((I16+J16+K16)=0,0,IF((I16+J16+K16)<=300000,0.015,IF((I16+J16+K16)<=500000,0.02,0.03))) -> 0 | AG16: 0 | AH16: =1-AG16 -> 1 | AI16: =IF(AH16>=1,1,AH16) -> 1 | AJ16: =IF(AG16=0,"DST","POSP RM") -> DST
A17: 16 | B17: Khushbu Chhajer | C17: ='Employee Master'!H29 -> 38200 | D17: ='Employee Master'!N29 -> 229200 | W17: =((IF(U17="Yes",F17*1.25,F17)+IF(U17="Yes",IF(H17="Annual",G17,IF(H17="2-Year",G17/2*1.25,IF(H17="3-Year",G17/3*1.5,IF(H17="Quarterly/HY",G17*0.5,G17))))*1.25,IF(H17="Annual",G17,IF(H17="2-Year",G17/2*1.25,IF(H17="3-Year",G17/3*1.5,IF(H17="Quarterly/HY",G17*0.5,G17)))))+(I17+J17+K17)+(L17+M17*0.2)+IF(U17="Yes",(N17-AE17)*1.25,(N17-AE17))+(O17*0.1+P17*0.075+Q17*0.05+R17*0.1)+(S17*0.3+T17*0.15)))*AI17 -> 0 | X17: =IF(D17=0,0,W17/D17) -> 0 | Y17: =IF(X17<0.8,"Below 80%",IF(X17<=1,"80-100%",IF(X17<=1.1,"101-110%",IF(X17<=1.3,"111-130%",IF(X17<=1.5,"131-150%","150%+"))))) -> Below 80% | Z17: =IF(AJ17="DST",IF(X17<0.8,0,IF(X17<=1,0.04,IF(X17<=1.1,0.05,IF(X17<=1.3,0.06,IF(X17<=1.5,0.07,0.08))))),IF(X17<0.8,0,IF(X17<=1,0.012,IF(X17<=1.1,0.015,IF(X17<=1.3,0.018,IF(X17<=1.5,0.021,0.02)))))) -> 0 | AA17: =W17*Z17 -> 0 | AB17: =C17+AA17 -> 38200 | AC17: =IF(W17>='Employee Master'!P29,"YES","NO") -> NO | AD17: =IF(X17>=1.3,"Star",IF(X17>=1,"High",IF(X17>=0.8,"Meets",IF(X17>=0.6,"Below","Non-Performer")))) -> Non-Performer | AE17: 0 | AF17: =IF((I17+J17+K17)=0,0,IF((I17+J17+K17)<=300000,0.015,IF((I17+J17+K17)<=500000,0.02,0.03))) -> 0 | AG17: 0 | AH17: =1-AG17 -> 1 | AI17: =IF(AH17>=1,1,AH17) -> 1 | AJ17: =IF(AG17=0,"DST","POSP RM") -> DST
A18: 17 | B18: Dipankar Das | C18: ='Employee Master'!H31 -> 48200 | D18: ='Employee Master'!N31 -> 289200 | W18: =((IF(U18="Yes",F18*1.25,F18)+IF(U18="Yes",IF(H18="Annual",G18,IF(H18="2-Year",G18/2*1.25,IF(H18="3-Year",G18/3*1.5,IF(H18="Quarterly/HY",G18*0.5,G18))))*1.25,IF(H18="Annual",G18,IF(H18="2-Year",G18/2*1.25,IF(H18="3-Year",G18/3*1.5,IF(H18="Quarterly/HY",G18*0.5,G18)))))+(I18+J18+K18)+(L18+M18*0.2)+IF(U18="Yes",(N18-AE18)*1.25,(N18-AE18))+(O18*0.1+P18*0.075+Q18*0.05+R18*0.1)+(S18*0.3+T18*0.15)))*AI18 -> 0 | X18: =IF(D18=0,0,W18/D18) -> 0 | Y18: =IF(X18<0.8,"Below 80%",IF(X18<=1,"80-100%",IF(X18<=1.1,"101-110%",IF(X18<=1.3,"111-130%",IF(X18<=1.5,"131-150%","150%+"))))) -> Below 80% | Z18: =IF(AJ18="DST",IF(X18<0.8,0,IF(X18<=1,0.04,IF(X18<=1.1,0.05,IF(X18<=1.3,0.06,IF(X18<=1.5,0.07,0.08))))),IF(X18<0.8,0,IF(X18<=1,0.012,IF(X18<=1.1,0.015,IF(X18<=1.3,0.018,IF(X18<=1.5,0.021,0.02)))))) -> 0 | AA18: =W18*Z18 -> 0 | AB18: =C18+AA18 -> 48200 | AC18: =IF(W18>='Employee Master'!P31,"YES","NO") -> NO | AD18: =IF(X18>=1.3,"Star",IF(X18>=1,"High",IF(X18>=0.8,"Meets",IF(X18>=0.6,"Below","Non-Performer")))) -> Non-Performer | AE18: 0 | AF18: =IF((I18+J18+K18)=0,0,IF((I18+J18+K18)<=300000,0.015,IF((I18+J18+K18)<=500000,0.02,0.03))) -> 0 | AG18: 0 | AH18: =1-AG18 -> 1 | AI18: =IF(AH18>=1,1,AH18) -> 1 | AJ18: =IF(AG18=0,"DST","POSP RM") -> DST
A19: 18 | B19: Tanima Das | C19: ='Employee Master'!H33 -> 16209 | D19: ='Employee Master'!N33 -> 97254 | W19: =((IF(U19="Yes",F19*1.25,F19)+IF(U19="Yes",IF(H19="Annual",G19,IF(H19="2-Year",G19/2*1.25,IF(H19="3-Year",G19/3*1.5,IF(H19="Quarterly/HY",G19*0.5,G19))))*1.25,IF(H19="Annual",G19,IF(H19="2-Year",G19/2*1.25,IF(H19="3-Year",G19/3*1.5,IF(H19="Quarterly/HY",G19*0.5,G19)))))+(I19+J19+K19)+(L19+M19*0.2)+IF(U19="Yes",(N19-AE19)*1.25,(N19-AE19))+(O19*0.1+P19*0.075+Q19*0.05+R19*0.1)+(S19*0.3+T19*0.15)))*AI19 -> 0 | X19: =IF(D19=0,0,W19/D19) -> 0 | Y19: =IF(X19<0.8,"Below 80%",IF(X19<=1,"80-100%",IF(X19<=1.1,"101-110%",IF(X19<=1.3,"111-130%",IF(X19<=1.5,"131-150%","150%+"))))) -> Below 80% | Z19: =IF(AJ19="DST",IF(X19<0.8,0,IF(X19<=1,0.04,IF(X19<=1.1,0.05,IF(X19<=1.3,0.06,IF(X19<=1.5,0.07,0.08))))),IF(X19<0.8,0,IF(X19<=1,0.012,IF(X19<=1.1,0.015,IF(X19<=1.3,0.018,IF(X19<=1.5,0.021,0.02)))))) -> 0 | AA19: =W19*Z19 -> 0 | AB19: =C19+AA19 -> 16209 | AC19: =IF(W19>='Employee Master'!P33,"YES","NO") -> NO | AD19: =IF(X19>=1.3,"Star",IF(X19>=1,"High",IF(X19>=0.8,"Meets",IF(X19>=0.6,"Below","Non-Performer")))) -> Non-Performer | AE19: 0 | AF19: =IF((I19+J19+K19)=0,0,IF((I19+J19+K19)<=300000,0.015,IF((I19+J19+K19)<=500000,0.02,0.03))) -> 0 | AG19: 0 | AH19: =1-AG19 -> 1 | AI19: =IF(AH19>=1,1,AH19) -> 1 | AJ19: =IF(AG19=0,"DST","POSP RM") -> DST
A20: 19 | B20: Mrinmoy Choudhury | C20: ='Employee Master'!H34 -> 95833 | D20: ='Employee Master'!N34 -> 2204159 | W20: =((IF(U20="Yes",F20*1.25,F20)+IF(U20="Yes",IF(H20="Annual",G20,IF(H20="2-Year",G20/2*1.25,IF(H20="3-Year",G20/3*1.5,IF(H20="Quarterly/HY",G20*0.5,G20))))*1.25,IF(H20="Annual",G20,IF(H20="2-Year",G20/2*1.25,IF(H20="3-Year",G20/3*1.5,IF(H20="Quarterly/HY",G20*0.5,G20)))))+(I20+J20+K20)+(L20+M20*0.2)+IF(U20="Yes",(N20-AE20)*1.25,(N20-AE20))+(O20*0.1+P20*0.075+Q20*0.05+R20*0.1)+(S20*0.3+T20*0.15)))*AI20 -> 0 | X20: =IF(D20=0,0,W20/D20) -> 0 | Y20: =IF(X20<0.8,"Below 80%",IF(X20<=1,"80-100%",IF(X20<=1.1,"101-110%",IF(X20<=1.3,"111-130%",IF(X20<=1.5,"131-150%","150%+"))))) -> Below 80% | Z20: =IF(AJ20="DST",IF(X20<0.8,0,IF(X20<=1,0.04,IF(X20<=1.1,0.05,IF(X20<=1.3,0.06,IF(X20<=1.5,0.07,0.08))))),IF(X20<0.8,0,IF(X20<=1,0.012,IF(X20<=1.1,0.015,IF(X20<=1.3,0.018,IF(X20<=1.5,0.021,0.02)))))) -> 0 | AA20: =W20*Z20 -> 0 | AB20: =C20+AA20 -> 95833 | AC20: =IF(W20>='Employee Master'!P34,"YES","NO") -> NO | AD20: =IF(X20>=1.3,"Star",IF(X20>=1,"High",IF(X20>=0.8,"Meets",IF(X20>=0.6,"Below","Non-Performer")))) -> Non-Performer | AE20: 0 | AF20: =IF((I20+J20+K20)=0,0,IF((I20+J20+K20)<=300000,0.015,IF((I20+J20+K20)<=500000,0.02,0.03))) -> 0 | AG20: 0 | AH20: =1-AG20 -> 1 | AI20: =IF(AH20>=1,1,AH20) -> 1 | AJ20: =IF(AG20=0,"DST","POSP RM") -> DST
A21: 20 | B21: Banshika Agarwal | C21: ='Employee Master'!H36 -> 13507 | D21: ='Employee Master'!N36 -> 81042 | W21: =((IF(U21="Yes",F21*1.25,F21)+IF(U21="Yes",IF(H21="Annual",G21,IF(H21="2-Year",G21/2*1.25,IF(H21="3-Year",G21/3*1.5,IF(H21="Quarterly/HY",G21*0.5,G21))))*1.25,IF(H21="Annual",G21,IF(H21="2-Year",G21/2*1.25,IF(H21="3-Year",G21/3*1.5,IF(H21="Quarterly/HY",G21*0.5,G21)))))+(I21+J21+K21)+(L21+M21*0.2)+IF(U21="Yes",(N21-AE21)*1.25,(N21-AE21))+(O21*0.1+P21*0.075+Q21*0.05+R21*0.1)+(S21*0.3+T21*0.15)))*AI21 -> 0 | X21: =IF(D21=0,0,W21/D21) -> 0 | Y21: =IF(X21<0.8,"Below 80%",IF(X21<=1,"80-100%",IF(X21<=1.1,"101-110%",IF(X21<=1.3,"111-130%",IF(X21<=1.5,"131-150%","150%+"))))) -> Below 80% | Z21: =IF(AJ21="DST",IF(X21<0.8,0,IF(X21<=1,0.04,IF(X21<=1.1,0.05,IF(X21<=1.3,0.06,IF(X21<=1.5,0.07,0.08))))),IF(X21<0.8,0,IF(X21<=1,0.012,IF(X21<=1.1,0.015,IF(X21<=1.3,0.018,IF(X21<=1.5,0.021,0.02)))))) -> 0 | AA21: =W21*Z21 -> 0 | AB21: =C21+AA21 -> 13507 | AC21: =IF(W21>='Employee Master'!P36,"YES","NO") -> NO | AD21: =IF(X21>=1.3,"Star",IF(X21>=1,"High",IF(X21>=0.8,"Meets",IF(X21>=0.6,"Below","Non-Performer")))) -> Non-Performer | AE21: 0 | AF21: =IF((I21+J21+K21)=0,0,IF((I21+J21+K21)<=300000,0.015,IF((I21+J21+K21)<=500000,0.02,0.03))) -> 0 | AG21: 0 | AH21: =1-AG21 -> 1 | AI21: =IF(AH21>=1,1,AH21) -> 1 | AJ21: =IF(AG21=0,"DST","POSP RM") -> DST
A22: 21 | B22: Banajit Bezbaruah | C22: ='Employee Master'!H39 -> 30363 | D22: ='Employee Master'!N39 -> 182178 | W22: =((IF(U22="Yes",F22*1.25,F22)+IF(U22="Yes",IF(H22="Annual",G22,IF(H22="2-Year",G22/2*1.25,IF(H22="3-Year",G22/3*1.5,IF(H22="Quarterly/HY",G22*0.5,G22))))*1.25,IF(H22="Annual",G22,IF(H22="2-Year",G22/2*1.25,IF(H22="3-Year",G22/3*1.5,IF(H22="Quarterly/HY",G22*0.5,G22)))))+(I22+J22+K22)+(L22+M22*0.2)+IF(U22="Yes",(N22-AE22)*1.25,(N22-AE22))+(O22*0.1+P22*0.075+Q22*0.05+R22*0.1)+(S22*0.3+T22*0.15)))*AI22 -> 0 | X22: =IF(D22=0,0,W22/D22) -> 0 | Y22: =IF(X22<0.8,"Below 80%",IF(X22<=1,"80-100%",IF(X22<=1.1,"101-110%",IF(X22<=1.3,"111-130%",IF(X22<=1.5,"131-150%","150%+"))))) -> Below 80% | Z22: =IF(AJ22="DST",IF(X22<0.8,0,IF(X22<=1,0.04,IF(X22<=1.1,0.05,IF(X22<=1.3,0.06,IF(X22<=1.5,0.07,0.08))))),IF(X22<0.8,0,IF(X22<=1,0.012,IF(X22<=1.1,0.015,IF(X22<=1.3,0.018,IF(X22<=1.5,0.021,0.02)))))) -> 0 | AA22: =W22*Z22 -> 0 | AB22: =C22+AA22 -> 30363 | AC22: =IF(W22>='Employee Master'!P39,"YES","NO") -> NO | AD22: =IF(X22>=1.3,"Star",IF(X22>=1,"High",IF(X22>=0.8,"Meets",IF(X22>=0.6,"Below","Non-Performer")))) -> Non-Performer | AE22: 0 | AF22: =IF((I22+J22+K22)=0,0,IF((I22+J22+K22)<=300000,0.015,IF((I22+J22+K22)<=500000,0.02,0.03))) -> 0 | AG22: 0 | AH22: =1-AG22 -> 1 | AI22: =IF(AH22>=1,1,AH22) -> 1 | AJ22: =IF(AG22=0,"DST","POSP RM") -> DST
A23: 22 | B23: Kshetrimayam AK Singh | C23: ='Employee Master'!H40 -> 44035 | D23: ='Employee Master'!N40 -> 880700 | W23: =((IF(U23="Yes",F23*1.25,F23)+IF(U23="Yes",IF(H23="Annual",G23,IF(H23="2-Year",G23/2*1.25,IF(H23="3-Year",G23/3*1.5,IF(H23="Quarterly/HY",G23*0.5,G23))))*1.25,IF(H23="Annual",G23,IF(H23="2-Year",G23/2*1.25,IF(H23="3-Year",G23/3*1.5,IF(H23="Quarterly/HY",G23*0.5,G23)))))+(I23+J23+K23)+(L23+M23*0.2)+IF(U23="Yes",(N23-AE23)*1.25,(N23-AE23))+(O23*0.1+P23*0.075+Q23*0.05+R23*0.1)+(S23*0.3+T23*0.15)))*AI23 -> 0 | X23: =IF(D23=0,0,W23/D23) -> 0 | Y23: =IF(X23<0.8,"Below 80%",IF(X23<=1,"80-100%",IF(X23<=1.1,"101-110%",IF(X23<=1.3,"111-130%",IF(X23<=1.5,"131-150%","150%+"))))) -> Below 80% | Z23: =IF(AJ23="DST",IF(X23<0.8,0,IF(X23<=1,0.04,IF(X23<=1.1,0.05,IF(X23<=1.3,0.06,IF(X23<=1.5,0.07,0.08))))),IF(X23<0.8,0,IF(X23<=1,0.012,IF(X23<=1.1,0.015,IF(X23<=1.3,0.018,IF(X23<=1.5,0.021,0.02)))))) -> 0 | AA23: =W23*Z23 -> 0 | AB23: =C23+AA23 -> 44035 | AC23: =IF(W23>='Employee Master'!P40,"YES","NO") -> NO | AD23: =IF(X23>=1.3,"Star",IF(X23>=1,"High",IF(X23>=0.8,"Meets",IF(X23>=0.6,"Below","Non-Performer")))) -> Non-Performer | AE23: 0 | AF23: =IF((I23+J23+K23)=0,0,IF((I23+J23+K23)<=300000,0.015,IF((I23+J23+K23)<=500000,0.02,0.03))) -> 0 | AG23: 0 | AH23: =1-AG23 -> 1 | AI23: =IF(AH23>=1,1,AH23) -> 1 | AJ23: =IF(AG23=0,"DST","POSP RM") -> DST
A24: 23 | B24: Shoibam Nara Singh | C24: ='Employee Master'!H41 -> 41534 | D24: ='Employee Master'!N41 -> 830680 | W24: =((IF(U24="Yes",F24*1.25,F24)+IF(U24="Yes",IF(H24="Annual",G24,IF(H24="2-Year",G24/2*1.25,IF(H24="3-Year",G24/3*1.5,IF(H24="Quarterly/HY",G24*0.5,G24))))*1.25,IF(H24="Annual",G24,IF(H24="2-Year",G24/2*1.25,IF(H24="3-Year",G24/3*1.5,IF(H24="Quarterly/HY",G24*0.5,G24)))))+(I24+J24+K24)+(L24+M24*0.2)+IF(U24="Yes",(N24-AE24)*1.25,(N24-AE24))+(O24*0.1+P24*0.075+Q24*0.05+R24*0.1)+(S24*0.3+T24*0.15)))*AI24 -> 0 | X24: =IF(D24=0,0,W24/D24) -> 0 | Y24: =IF(X24<0.8,"Below 80%",IF(X24<=1,"80-100%",IF(X24<=1.1,"101-110%",IF(X24<=1.3,"111-130%",IF(X24<=1.5,"131-150%","150%+"))))) -> Below 80% | Z24: =IF(AJ24="DST",IF(X24<0.8,0,IF(X24<=1,0.04,IF(X24<=1.1,0.05,IF(X24<=1.3,0.06,IF(X24<=1.5,0.07,0.08))))),IF(X24<0.8,0,IF(X24<=1,0.012,IF(X24<=1.1,0.015,IF(X24<=1.3,0.018,IF(X24<=1.5,0.021,0.02)))))) -> 0 | AA24: =W24*Z24 -> 0 | AB24: =C24+AA24 -> 41534 | AC24: =IF(W24>='Employee Master'!P41,"YES","NO") -> NO | AD24: =IF(X24>=1.3,"Star",IF(X24>=1,"High",IF(X24>=0.8,"Meets",IF(X24>=0.6,"Below","Non-Performer")))) -> Non-Performer | AE24: 0 | AF24: =IF((I24+J24+K24)=0,0,IF((I24+J24+K24)<=300000,0.015,IF((I24+J24+K24)<=500000,0.02,0.03))) -> 0 | AG24: 0 | AH24: =1-AG24 -> 1 | AI24: =IF(AH24>=1,1,AH24) -> 1 | AJ24: =IF(AG24=0,"DST","POSP RM") -> DST
A25: 24 | B25: Tasdiq Ahmed | C25: ='Employee Master'!H42 -> 18009 | D25: ='Employee Master'!N42 -> 108054 | W25: =((IF(U25="Yes",F25*1.25,F25)+IF(U25="Yes",IF(H25="Annual",G25,IF(H25="2-Year",G25/2*1.25,IF(H25="3-Year",G25/3*1.5,IF(H25="Quarterly/HY",G25*0.5,G25))))*1.25,IF(H25="Annual",G25,IF(H25="2-Year",G25/2*1.25,IF(H25="3-Year",G25/3*1.5,IF(H25="Quarterly/HY",G25*0.5,G25)))))+(I25+J25+K25)+(L25+M25*0.2)+IF(U25="Yes",(N25-AE25)*1.25,(N25-AE25))+(O25*0.1+P25*0.075+Q25*0.05+R25*0.1)+(S25*0.3+T25*0.15)))*AI25 -> 0 | X25: =IF(D25=0,0,W25/D25) -> 0 | Y25: =IF(X25<0.8,"Below 80%",IF(X25<=1,"80-100%",IF(X25<=1.1,"101-110%",IF(X25<=1.3,"111-130%",IF(X25<=1.5,"131-150%","150%+"))))) -> Below 80% | Z25: =IF(AJ25="DST",IF(X25<0.8,0,IF(X25<=1,0.04,IF(X25<=1.1,0.05,IF(X25<=1.3,0.06,IF(X25<=1.5,0.07,0.08))))),IF(X25<0.8,0,IF(X25<=1,0.012,IF(X25<=1.1,0.015,IF(X25<=1.3,0.018,IF(X25<=1.5,0.021,0.02)))))) -> 0 | AA25: =W25*Z25 -> 0 | AB25: =C25+AA25 -> 18009 | AC25: =IF(W25>='Employee Master'!P42,"YES","NO") -> NO | AD25: =IF(X25>=1.3,"Star",IF(X25>=1,"High",IF(X25>=0.8,"Meets",IF(X25>=0.6,"Below","Non-Performer")))) -> Non-Performer | AE25: 0 | AF25: =IF((I25+J25+K25)=0,0,IF((I25+J25+K25)<=300000,0.015,IF((I25+J25+K25)<=500000,0.02,0.03))) -> 0 | AG25: 0 | AH25: =1-AG25 -> 1 | AI25: =IF(AH25>=1,1,AH25) -> 1 | AJ25: =IF(AG25=0,"DST","POSP RM") -> DST
A26: 25 | B26: Hemanta Saharia | C26: ='Employee Master'!H43 -> 66117 | D26: ='Employee Master'!N43 -> 1322340 | W26: =((IF(U26="Yes",F26*1.25,F26)+IF(U26="Yes",IF(H26="Annual",G26,IF(H26="2-Year",G26/2*1.25,IF(H26="3-Year",G26/3*1.5,IF(H26="Quarterly/HY",G26*0.5,G26))))*1.25,IF(H26="Annual",G26,IF(H26="2-Year",G26/2*1.25,IF(H26="3-Year",G26/3*1.5,IF(H26="Quarterly/HY",G26*0.5,G26)))))+(I26+J26+K26)+(L26+M26*0.2)+IF(U26="Yes",(N26-AE26)*1.25,(N26-AE26))+(O26*0.1+P26*0.075+Q26*0.05+R26*0.1)+(S26*0.3+T26*0.15)))*AI26 -> 0 | X26: =IF(D26=0,0,W26/D26) -> 0 | Y26: =IF(X26<0.8,"Below 80%",IF(X26<=1,"80-100%",IF(X26<=1.1,"101-110%",IF(X26<=1.3,"111-130%",IF(X26<=1.5,"131-150%","150%+"))))) -> Below 80% | Z26: =IF(AJ26="DST",IF(X26<0.8,0,IF(X26<=1,0.04,IF(X26<=1.1,0.05,IF(X26<=1.3,0.06,IF(X26<=1.5,0.07,0.08))))),IF(X26<0.8,0,IF(X26<=1,0.012,IF(X26<=1.1,0.015,IF(X26<=1.3,0.018,IF(X26<=1.5,0.021,0.02)))))) -> 0 | AA26: =W26*Z26 -> 0 | AB26: =C26+AA26 -> 66117 | AC26: =IF(W26>='Employee Master'!P43,"YES","NO") -> NO | AD26: =IF(X26>=1.3,"Star",IF(X26>=1,"High",IF(X26>=0.8,"Meets",IF(X26>=0.6,"Below","Non-Performer")))) -> Non-Performer | AE26: 0 | AF26: =IF((I26+J26+K26)=0,0,IF((I26+J26+K26)<=300000,0.015,IF((I26+J26+K26)<=500000,0.02,0.03))) -> 0 | AG26: 0 | AH26: =1-AG26 -> 1 | AI26: =IF(AH26>=1,1,AH26) -> 1 | AJ26: =IF(AG26=0,"DST","POSP RM") -> DST
